Workbook
Name ActivityID: '[1]FIN & ACCT ONLY'!$J$45
Name BillingLine: [1]Pulldowns!$A$1:$A$27
Name fundsource: [1]Pulldowns!$C$2:$C$43
Name Ineligible: 'standard activities'!$Q$3
Name PROJ: 'POM Section'!#REF!
Name PROJ: 'POM Section'!#REF!
Name Sequence: [1]Pulldowns!$B$1:$B$10
Name Types: PullDowns!$C$2:$C$13

Sheet POM  Section
B2: SDOT Activity Set-Up Form | J2: Requested By: | O2: =IF(E9="No","SPEND PLAN NEEDED","")
B3: Project Owner & Manager Section | J3: David Burgesser
B5: General Information
B6: Proposed Activity Description | E6: 21st Ave S - Bayview to Walker | H6: Current Year Estimated Spend | K6: 20000
B7: Detail Project Number | E7: TRC0338 | H7: Total Estimated Spend | K7: 350000
B8: Detail Project Description | E8: Low Cost Sidewalks | H8: Will this work create or improve an SDOT asset? | K8: Yes
B9: Is the PPM Detail Project Setup? | E9: Yes | H9: PPM Detail Project ID | K9: TRC0338_WP00000038
B11: Scope of Work (please include phase, location, and extents if relevant)
B12: Design and construct a new walkway with traffic calming and crossing improvements on 21st Ave S between S Bayview St and S Walker St. Council District 2, near Lake Washington Girls Middle School and the Giddens School.
B21: Activity Details
B22: Reimbursable? | D22: NA | H22: If Standard, which? | J22: S0300 Construction
B23: Activity Type/Phase | D23: Construction | H23: Labor Charges OK? | J23: Yes
B24: Standard or Unique? | D24: Standard | H24: Suggested Prefix | J24: =IFERROR(VLOOKUP(D22&D24,prefix!A1:B5,2,FALSE),"-") -> S
B26: Will expenditures in this activity relate to any of the following? Select all that apply.
B27: Grant | J27: Work in Disadvantaged Areas
B28: Interdepartmental MOA / MOU | J28: Accident Claim
B29: Interlocal Agency Agreement | J29: Permit
B30: Contract with Private Party | J30: Mitigation Deposit
B31: Move Seattle Levy Deliverable | J31: Council Budget Amendment | K31: SDOT-105-B-001
B32: Work within School Zones | J32: Other Restricted Funds
B33: If yes to any items in this section, please attach a copy of the agreement or other relevant documentation.
C36: When complete, please email this form to the appropriate Finance Analyst, and copy the Project Owner (if applicable), Project Controls at DOT_Project_Controls@seattle.gov, and the Project Manager (if applicable). Finance will assume that all copied parties agree to this setup. Project Owners and Project Managers should ensure this work is reflected in the current spend plan for the project and/or program.

Sheet FA Section
B2: SDOT Activity Set-Up Form | I2: Requesting Finance Analyst:
B3: Finance Section
B4: General Project Information
B5: Suggested Activity Description* | E5: ='POM Section'!E6:G6 -> 21st Ave S - Bayview to Walker | H5: Current Year Estimated Spend | K5: ='POM Section'!K6:L6 -> 20000
B6: Detail Project Number* | E6: ='POM Section'!E7:G7 -> TRC0338 | H6: Total Estimated Spend | K6: ='POM Section'!K7:L7 -> 350000
B7: Detail Project Name* | E7: ='POM Section'!E8:G8 -> Low Cost Sidewalks | H7: Will this activity create or improve an SDOT asset?* | K7: ='POM Section'!K8 -> Yes
B9: Funding Details
B11: Will activity require a SpeedType/SpeedChart? | H11: If Yes, select prime fund:
B13: Will Funds distribution be setup at the Activity Level?*
D14: If Yes, overhead rate plan will be applied at the activity level. For exceptions, select:
D15: If Yes fill out Funds Distribution below:
B17: Sequence 1 | D17: Optional Start Date | H17: Threshold
C18: Line | D18: Fund | G18: Funding Source | I18: Percent | J18: Line Threshold
C19: 1 | J19: =I19*I17 -> 0
C20: 2 | J20: =I20*I17 -> 0
C21: 3 | J21: =I21*I17 -> 0
I22: =SUM(I19:I21) -> 0
B23: Sequence 2 | D23: Optional Start Date | H23: Threshold
C24: Line | D24: Fund | G24: Funding Source | I24: Percent | J24: Line Threshold
C25: 1 | J25: =I25*I23 -> 0
C26: 2 | J26: =I26*I23 -> 0
C27: 3 | J27: =I27*I23 -> 0
I28: =IF(SUM(I25:I27)=1," ",SUM(I25:I27)) -> 0
B29: Sequence 3 | D29: Optional Start Date | H29: Threshold
C30: Line | D30: Fund | G30: Funding Source | I30: Percent | J30: Line Threshold
C31: 1 | J31: =I31*I29 -> 0
C32: 2 | J32: =I32*I29 -> 0
C33: 3 | J33: =I33*I29 -> 0
I34: =SUM(I31:I33) -> 0
B36: * Indicates required field

Sheet FA Section - Grants
B2: SDOT Activity Set-Up Form for Grants | I2: Requesting Finance Analyst:
B3: Finance Section
B4: General Project Information
B5: Suggested Activity Description* | E5: ='POM Section'!E6:G6 -> 21st Ave S - Bayview to Walker | H5: Current Year Estimated Spend | K5: ='POM Section'!K6:L6 -> 20000
B6: Detail Project Number* | E6: ='POM Section'!E7:G7 -> TRC0338 | H6: Total Estimated Spend | K6: ='POM Section'!K7:L7 -> 350000
B7: Detail Project Name* | E7: ='POM Section'!E8:G8 -> Low Cost Sidewalks | H7: Will this activity create or improve an SDOT asset?* | K7: ='POM Section'!K8 -> Yes
B9: Collection Activity Details | H9: Billing Activity Details
B10: Activity Type* | H10: Activity Type | I10: Grant
B11: Standard or Unique?* | H11: Standard or Unique?* | I11: Standard
B12: If Standard, which? | H12: If Standard, which? | I12: =IFERROR(VLOOKUP(D12,'standard activities'!S2:T14,2,FALSE),0) -> 0
B13: Suggested Prefix | D13: =IFERROR(VLOOKUP($D$11,prefix!$A$9:$B$10,2,FALSE),"-") -> - | H13: Suggested Prefix | I13: =IFERROR(VLOOKUP(I11,prefix!A13:B14,2,FALSE),0) -> GS
B14: Labor Charges OK?* | H14: Labor Charges OK? | I14: No
B16: Ineligible Activity Details
B17: Has an ineligible activity been set up for this phase?
E18: If yes, enter # here.
E19: If blank, Accounting will set up the activity based on the fields below with a status of N - No labor and no funds distribution.
B20: Activity Type | D20: =IF(H18=0,(D10),) -> 0 | H20: If Standard, which? | J20: =IFERROR(VLOOKUP(D20,'standard activities'!P4:Q5,2,FALSE),0) -> 0
B21: Standard or Unique? | D21: =IF(D20="Design","Standard",IF(D20="Construction","Standard","Unique")) -> Unique | H21: Suggested Prefix | J21: =VLOOKUP($D$21,prefix!$A$9:$B$10,2,FALSE) -> UG
B22: Labor Charges OK? | C22: No | D22: NO | H22: Suggested Description | J22: =IF(H18=0,IF(J20=0,E5&" - "&"Ineligible","-"),"-") -> 21st Ave S - Bayview to Walker - Ineligible
B24: Collection Activity Funding Details
B25: Please select the prime fund for the SpeedType/SpeedChart:
D27: Overhead rate plan will be applied at the activity level. For exceptions, select:
AG28: Column2
P29: Sequence 1: The purpose of this sequence is to divert ineligible equipment and 1% for art costs from being funds distributed to the grant billing activity. The threshold should be set artificially high in order to prevent ineligible costs being funds distributed to the grant billing activity. The fund/fund source should be local funds budgeted to the project. If 1% Art should happen to hit the grant collection activity, it MUST be transferred to the 1% for Art activity (S0405). | AF29: inelig | AG29: =IF(H18=0,IF(J20=0,J22,J20),H18) -> 21st Ave S - Bayview to Walker - Ineligible
B30: Sequence 1 | D30: Optional Start Date | H30: Threshold | AF30: billing | AG30: =IF(I12=0,"New Billing Activity",I12) -> New Billing Activity
B31: Line | C31: Source | D31: Fund | G31: Funding Source | I31: Percent | J31: Line Threshold | K31: Target Activity | AF31: collection | AG31: =IF(D12=0,"New Collection Activity",D12) -> New Collection Activity
B32: 1 | C32: Equipment & 1% for Art | J32: =I32*I30 -> 0
B33: 2 | C33: Equipment & 1% for Art | J33: =I33*I30 -> 0
I34: =IF(SUM(I31:I33)=1," ",SUM(I31:I33)) -> 0
B35: Sequence 2 | D35: Optional Start Date | H35: Threshold | P35: Sequence 2: If labor will be charged to the grant activity the purpose of this sequence is to divert ineligible indirect/overhead labor costs from being funds distributed to the grant billing activity. The grant ineligible calculator can be used to calculate the threshold amount. If costs exceed the threshold, the result will be an ODL as they will not funds distribute to the grant billing activity. If labor will not be charged to the grant collection activity then use this sequence for eligible grant costs as noted below under Sequence 3.
B36: Line | C36: Source | D36: Fund | G36: Funding Source | I36: Percent | J36: Line Threshold | K36: Target Activity
B37: 1 | J37: =I37*I35 -> 0
B38: 2 | J38: =I38*I35 -> 0
B39: 3 | J39: =I39*I35 -> 0
I40: =IF(SUM(I37:I39)=1," ",SUM(I37:I39)) -> 0 | P40: Grant Ineligible Calculator
B41: Sequence 3 | D41: Optional Start Date | H41: Threshold
B42: Line | C42: Source | D42: Fund | G42: Funding Source | I42: Percent | J42: Line Threshold | K42: Target Activity | P42: Sequence 3: The purpose of this sequence is to funds distribute eligible grant costs to the grant billing activity. The threshold will be the grant award plus any required match. As noted above under Sequence 2, if no labor will be charged to the grant collection activity then use Sequence 2 as the first sequence for eligible grant costs. The first line will be the costs to be distributed (i.e. reimbursed by) the grant. Subsequent lines are needed when the grant has a matching requirement. Match is generally paid for by a local source of funds. However, state grants can also be used to match federal grants. Grant funding sources are not maintained for the drop down list. You will need to hard code the grant funding source into this form.
B43: 1 | J43: =I43*I41 -> 0
B44: 2 | J44: =I44*I41 -> 0
B45: 3 | J45: =I45*I41 -> 0
...

Sheet PullDowns
A1: PullDowns | B1: Rate Plan | C1: Types | D1: Labor Charges OK? | E1: Asset? | F1: Prime Fund | G1: Fund | H1: Funding Sources | I1: BSL Project | J1: BSL Program | K1: Activity Billing | L1: Reimbursment Types | M1: Standard or Unique - Reimb | N1: Standard or Unique-N/A | O1: Standard or Unique-Grant | P1: Detail Project | Q1: Source | S1: PPM Detail Proj Setup?
A2: Password:Dropdown | B2: No Overhead - detail project will only collect indirect costs | C2: Initiation | D2: Yes | E2: Yes | F2: 00100 GENERAL FUND | G2: 00100 GENERAL FUND | H2: <No Funding Source> | I2: None | J2: None | K2: Reimbursable | L2: Allocations | M2: Unique | N2: Standard | O2: Standard | P2: TR80001 SU-PIBs Recovery | Q2: All Transactions | S2: Yes
B3: Other - documentation and Finance Manager approval required | C3: PrePlanning | D3: No | E3: No | F3: 10398 MOVE SEATTLE PROPERTY TAX LEVY | G3: 00164 CUM RES CAP PROJ UNRESTR FUND | H3: CTR00010 Deposits - Private/Other | K3: NA | L3: Contract Billing | N3: Unique | O3: Unique | P3: TR80002 SU Revenue Center | Q3: Equipment & 1% for Art | S3: No
C4: Planning | F4: 13000 TRANSPORTATION FUND | G4: 10102 EMERGENCY FUND | H4: CTR000M1 Mitigation | L4: Billing Module | P4: TR80003 SU-Access Seattle | Q4: Eligible - Most Grants
C5: Acquisition | F5: 30010 REET I CAPITAL PROJECTS | G5: 10394 LEVY LID LIFT | H5: CTR000M2 Mitigation - Pro-rata Share | L5: Interfund Revenue or Expense (Journal Entry) | P5: TR80004 SU-Cprs Insp Cost Ctr | Q5: Ineligible - Most Grants
C6: Design | F6: 30020 REET II CAPITAL PROJECTS | G6: 10398 MOVE SEATTLE PROPERTY TAX LEVY | H6: CTR000M3 Mitigation - Voluntary, Northgate | P6: TR80005 SU-Development Review | Q6: Eligible - TIB Grants
C7: Construction | G7: 10800 SEATTLE STREETCAR OPERATING FUND | H7: CTR000M4 Mitigation - Voluntary, South Lake Union | P7: TR80006 SU-District Inspect & Coord | Q7: Ineligible - TIB Grants
C8: Close | G8: 13000 TRANSPORTATION FUND | H8: CTR000PB Partnership - BNSF | P8: TR80007 SU-Division Management
C9: Ops and Maint | G9: 18500 SCHOOL SAFETY TRAFFIC AND PEDESTRIAN IMPROVEMENT FUND | H9: CTR000PB Partnership - BNSF | P9: TR80008 SU-Emergency Response
C10: Gen and Admin | G10: 19900 TRANSPORTATION BENEFIT DIST FD | H10: CTR000PK Partnership - King County | P10: TR80009 SU-Inspector Investigations
C11: Reimbursable | G11: 30010 REET I CAPITAL PROJECTS | H11: CTR000PK Partnership - King County | P11: TR80010 SU-Major Projects Cost Ctr
C12: Revenue Only | G12: 30020 REET II CAPITAL PROJECTS | H12: CTR000PP Partnership - Port of Seattle | P12: TR80011 SU-Policy Planning Cost Ctr
G13: 33850 2000 PARKS LEVY FUND | H13: CTR000PP Partnership - Port of Seattle | P13: TR80012 SU-ProjDev Cost Ctr
G14: 33860 2008 PARKS LEVY FUND | H14: CTR000PS Partnership - Sound Transit | P14: TR80013 SU-Project Coordination
G15: 35040 WATERFRONT LID FUND | H15: CTR000PS Partnership - Sound Transit | P15: TR80014 SU-PSM Code Compliance
G16: 35200 2008 MULTIPURPOSE LTGO BOND FD | H16: CTR000PW Partnership - WSDOT | P16: TR80015 SU-Public Space Program Dvlpmt
G17: 35300 2009 MULTIPURPOSE LTGO BOND | H17: CTR000PW Partnership - WSDOT | P17: TR80016 SU-Shared Cost Projects
G18: 35400 2010 MULTIPURPOSE LTGO BOND FD | H18: OTR00041 Interfund Loan - South Lake Union Streetcar Operating | P18: TR80017 SU-Shoring
G19: 35500 2011 MULTIPURPOSE LTGO BOND FD | H19: OTR00042 Interfund Loan - Streetcar Capital | P19: TR80018 SU-Site Plan Review
G20: 35600 2012 LTGO BOND FUND | H20: OTR0004C Interfund Loan - Central Waterfront | P20: TR80019 SU-St Maint Insp Cost Ctr
G21: 35700 2013 LTGO SERIES A NON-TAXABLE | H21: OTR0004M Interfund Loan - Mercer | P21: TR80020 SU-Street Improvmnt Inspection
G22: 35800 ALASKAN WAY SEAWALL CONST FUND | H22: OTR00050 LID - Central Waterfront | P22: TR80021 SU-Street Improvement Review
G23: 35820 2014 UTGO- ALASKAWAY SEAWALL | H23: OTR00060 Loan - Public Works Trust Fund | P23: TR80022 SU- Code Development & Coordin
G24: 35830 2015 UTGO AWVS | H24: OTR00070 Philanthropy - Central Waterfront | P24: TR80023 SU-Street Use Data and GIS
... G41: 36910 2022 LTGO Taxable Bond Fund | H41: OTRVLF60 Vehicle License Fee - $60 | P41: TR80041 Car Sharing - Revenue
H42: RTRSCL SCL Reimbursable | P42: TR80042 Carpool - Expenditures
H43: RTRSPUDWW SPU Drainage&Wastewater Reimb | P43: TR80043 Carpool - Revenues
H44: RTRSPUWF SPU Water Fund Reimbursable | P44: TR80044 RPZ - Expenditures
P45: TR80045 RPZ - Revenues
P46: TR80046 RPZ - Special Projects
P47: TR80047 Shoreline St Ends Revenue
P48: TR90001 Equipment Cost Center
P49: TR90002 Equipment Recovery
P50: TR90003 Rubble Haul Cost Center
P51: TR90004 Rubble Haul Recovery
P52: TR90005 Sign Shop Cost Center
P53: TR90006 Sign Shop Recovery
P54: TRA0001 Judgement and Claims
P55: TRA0002 SRI - Capital GF
P56: TRA0003 SRI - Capital OTH
...

Sheet Source Definitions
A1: Source Definitions Cheat Sheet
A2: From PCA 0401 Setup Fund Distribution Rules 12/13/17
A4: For Finance Analysts
B6: Type of Grant Restrictions | C6: Sources to Include as Eligible Costs (target = collection & billing activities) | E6: Sources to Exclude As Inelgibile Costs (target = ineligible activity)
B7: Not a grant, or grant has no eligibility restrictions. | C7: All Transactions Includes analys types PAY, IPB, ITO, ICT, IDV, IDP, ACT, GLE, ALE with no restrictions by account, Resource Type, or SCAT. | E7: N/A
B8: All Grants | E8: Equipment & 1% for Art Includes any transaction with an equipment or 1% for art account number. This source must always be handled FIRST in funds distribution, and if threshold must be kept above total costs at all times to avoid billing equipment or art costs to a grant.
B9: Most Grants | C9: Grant Eligible (Most Grants) Includes all expenditure transactions except Citywide, Departmental and Divisional Overhead. Also includes part of the Time Off and Pooled Benefit rate (anything up to the max allowable amount calculated yearly by accounting). | E9: Grant Ineligible (Most Grants) Includes Citwide, Departmental and Divisional Overhead. Includes ineligible part of the Time Off and Pooled Benefit rate (anything in excess of the accounting calculated rate).
B10: TIB Grants | C10: Grant Eligible (TIB) Includes all expenditure transactions except Citwide, Departmental and Divisional Overhead. Also includes part the Time Off and Pooled Benefit rate (up to the max of 50% allowed). | E10: Grant Ineligible (TIB) Includes Citwide, Departmental and Divisional Overhead. Includes ineligible part of the Time Off and Pooled Benefit rate (anything in excess of 50% max allowed).
A12: For Project Cost
B14: Source on Activity Form | C14: Analysis Type | D14: Source Type | E14: Account | F14: SCAT
B15: All Transactions | C15: PAY | D15: % | E15: % | F15: %
C16: ITO | D16: % | E16: % | F16: %
C17: IPB | D17: % | E17: % | F17: %
C18: ICT | D18: % | E18: % | F18: %
C19: IDV | D19: % | E19: % | F19: %
C20: IDP | D20: % | E20: % | F20: %
C21: ACT | D21: % | E21: % | F21: %
C22: GLE | D22: % | E22: % | F22: %
C23: ALE | D23: % | E23: % | F23: %
B24: Grant Eligible (Most) | C24: PAY | D24: LABOR | E24: % | F24: %
C25: PAY | D25: FRNG | E25: % | F25: %
C26: ITO | D26: % | E26: % | F26: ELT
C27: IPB | D27: % | E27: % | F27: ELT
C28: IPB | D28: % | E28: % | F28: ELI
C29: ACT | D29: % | E29: % | F29: %
C30: GLE | D30: % | E30: % | F30: %
C31: ALE | D31: % | E31: % | F31: %
B32: Grant Ineligible (Most) | C32: ITO | D32: % | E32: % | F32: INE
C33: IPB | D33: % | E33: % | F33: INE
C34: ICT | D34: % | E34: % | F34: %
C35: IDV | D35: % | E35: % | F35: %
C36: IDP | D36: % | E36: % | F36: %
B37: Grant Eligible (TIB) | C37: PAY | D37: LABOR | E37: % | F37: %
C38: PAY | D38: FRNG | E38: 520300 | F38: %
C39: PAY | D39: FRNG | E39: 520020 | F39: %
C40: PAY | D40: FRNG | E40: 520010 | F40: %
C41: ITO | D41: % | E41: % | F41: ELT
C42: IPB | D42: % | E42: % | F42: ELT
C43: ACT | D43: % | E43: % | F43: %
C44: GLE | D44: % | E44: % | F44: %
...

Sheet standard activities
A1: NA | B1: NA | C1: NA | D1: NA | E1: NA | F1: NA | G1: NA | H1: NA | I1: NA | J1: NA | K1: Grant Collection | S1: Grant Billing
A2: Initiation | B2: PrePlanning | C2: Acquisition | D2: Planning | E2: Design | F2: Construction | G2: Close | H2: Ops and Maint | I2: Gen and Admin | J2: Revenue Only | P2: Ineligible by Type | S2: SG402 Education | T2: GS402 Education
A3: NAInitiation | B3: NAPrePlanning | C3: NAAcquisition | D3: NAPlanning | E3: NADesign | F3: NAConstruction | G3: NAClose | H3: NAOpsandMaint | I3: NAGenandAdmin | J3: NARevenueOnly | K3: StandardOpsandMaint | L3: StandardClose | M3: StandardDesign | N3: StandardConstruction | Q3: Ineligible | S3: SG403 Enforcement | T3: GS403 Enforcement
C4: S0200 Acquisition | D4: S0001 Planning | E4: S0100 Design & Environmental | F4: S0300 Construction | G4: S0400 Closeout | H4: S0106 Plan Dev/Review | I4: S1001 Debt Service | J4: S0907 Pay Station and Passes | K4: SG402 Education | L4: SG400 Closeout | M4: SG100 Design & Environmental | N4: SG300 Construction | P4: Design | Q4: SG103 Design - Ineligible | S4: SG400 Closeout | T4: GS400 Closeout
D5: S0106 Plan Dev/Review | E5: S0101 Design - Curb Ramp | F5: S0301 Construct - Stairway | G5: S0401 Landscape Establishment | H5: S0402 Education | I5: S1002 Collect Recovery | J5: S0908 Pay-by-Phone | K5: SG403 Enforcement | L5: SG402 Education | M5: SG101 Design - SDOT Labor | N5: SG301 Construction - SDOT Labor | P5: Construction | Q5: SG304 Construction - Ineligible | S5: SG402 Education | T5: GS402 Education
D6: S0107 Master Plan / Imp Plan | E6: S0102 Design - Drafting | F6: S0302 Construct - Stw Landscaping | G6: S0404 Performance Measurement | H6: S0403 Enforcement | I6: S1304 Mgmt & Admin | J6: S0909 Sound Transit Partnership | L6: SG403 Enforcement | M6: SG102 Design - Consultant | N6: SG302 Construction - Consultant | S6: SG403 Enforcement | T6: GS403 Enforcement
D7: S0108 Design Guidelines | E7: S0103 Design - Landscape | F7: S0303 Construct - Stw Pathway | G7: S0402 Education | H7: S0404 Performance Measurement | I7: S1305 Office Reconfiguration | J7: S0910 Streetcar Amazon Contract | N7: SG303 Construction - Contractor | S7: SG100 Design & Environmental | T7: GS100 Design & Environmental
D8: S0405 1% For Art | E8: S0104 Design - Review/Guidance | F8: S0304 Construct - Stw Rail | G8: S0403 Enforcement | H8: S0500 Emergency Response | I8: S1306 Policy / Proc / Improvement | J8: S0913 Streetcar Sponsorship | N8: SG305 Construction - Const Mgmt | S8: SG101 Design - SDOT Labor | T8: GS101 Design - SDOT Labor
D9: S1302 Data Collection/Analysis | E9: S0105 Design - Traffic Control | F9: S0305 Construct - Stw Site Prep | H9: S0501 Emergency Response Standby | I9: S1308 Training & Prof Dev | J9: S1204 Penalties | S9: SG102 Design - Consultant | T9: GS102 Design - Consultant
D10: S1307 Program Dev/Mgmt | E10: S1003 Engineering Reserve | H10: S0502 Cleaning - Path & Trail | S10: SG300 Construction | T10: GS300 Construction
H11: S0503 Cleaning - Street | S11: SG301 Construction - SDOT Labor | T11: GS301 Construction - SDOT Labor
H12: S0504 Cleanup - Encampment | S12: SG302 Construction - Consultant | T12: GS302 Construction - Consultant
H13: S0505 Cleaning Graffiti | S13: SG303 Construction - Contractor | T13: GS303 Construction - Contractor
H14: S0506 Install/Maint - Guardrail | S14: SG305 Construction - Const Mgmt | T14: GS305 Construction - Const Mgmt
H15: S0507 Install/Maint - Irrigation
H16: S0508 Install/Maint - Signs
H17: S0509 Install/Maint - Xwalk
H18: S0510 Maint - Bldg & Grounds
H19: S0511 Maint - Carpentry/Heavy
H20: S0512 Maint - Elevator
H21: S0513 Maint - General
H22: S0514 Maint - Sign
H23: S0515 Maint - Street Surface
H24: S0516 Maint - Street, Preventative
H25: S0517 Maint - Vehicle Special
H26: S0518 Pavement Marking
... H80: S1307 Program Dev/Mgmt

Sheet prefix
A1: NAStandard | B1: S
A2: GrantStandard | B2: SG
A3: ReimbursableUnique | B3: R
A4: NAUnique | B4: U
A5: GrantUnique | B5: UG
A8: Grant Collection
A9: Standard | B9: SG
A10: Unique | B10: UG
A12: Grant Billing
A13: Standard | B13: GS
A14: Unique | B14: GU
